2025-02-23 14:30:55,751 [WARNING]- Not Found: /favicon.ico
2025-02-23 14:33:25,441 [ERROR]- Internal Server Error: /facility/report/details/13001232CS/
Traceback (most recent call last):
  File "C:\Users\User\Desktop\Django\venv\Lib\site-packages\django\template\backends\django.py", line 107, in render
    return self.template.render(context)
           ^^^^^^^^^^^^^^^^^^^^^^^^^^^^^
  File "C:\Users\User\Desktop\Django\venv\Lib\site-packages\django\template\base.py", line 171, in render
    return self._render(context)
           ^^^^^^^^^^^^^^^^^^^^^
  File "C:\Users\User\Desktop\Django\venv\Lib\site-packages\django\test\utils.py", line 114, in instrumented_test_render
    return self.nodelist.render(context)
           ^^^^^^^^^^^^^^^^^^^^^^^^^^^^^
  File "C:\Users\User\Desktop\Django\venv\Lib\site-packages\django\template\base.py", line 1008, in render
    return SafeString("".join([node.render_annotated(context) for node in self]))
                               ^^^^^^^^^^^^^^^^^^^^^^^^^^^^^^
  File "C:\Users\User\Desktop\Django\venv\Lib\site-packages\django\template\base.py", line 969, in render_annotated
    return self.render(context)
           ^^^^^^^^^^^^^^^^^^^^
  File "C:\Users\User\Desktop\Django\venv\Lib\site-packages\django\template\loader_tags.py", line 159, in render
    return compiled_parent._render(context)
           ^^^^^^^^^^^^^^^^^^^^^^^^^^^^^^^^
  File "C:\Users\User\Desktop\Django\venv\Lib\site-packages\django\test\utils.py", line 114, in instrumented_test_render
    return self.nodelist.render(context)
           ^^^^^^^^^^^^^^^^^^^^^^^^^^^^^
  File "C:\Users\User\Desktop\Django\venv\Lib\site-packages\django\template\base.py", line 1008, in render
    return SafeString("".join([node.render_annotated(context) for node in self]))
                               ^^^^^^^^^^^^^^^^^^^^^^^^^^^^^^
  File "C:\Users\User\Desktop\Django\venv\Lib\site-packages\django\template\base.py", line 969, in render_annotated
    return self.render(context)
           ^^^^^^^^^^^^^^^^^^^^
  File "C:\Users\User\Desktop\Django\venv\Lib\site-packages\django\template\loader_tags.py", line 65, in render
    result = block.nodelist.render(context)
             ^^^^^^^^^^^^^^^^^^^^^^^^^^^^^^
  File "C:\Users\User\Desktop\Django\venv\Lib\site-packages\django\template\base.py", line 1008, in render
    return SafeString("".join([node.render_annotated(context) for node in self]))
                               ^^^^^^^^^^^^^^^^^^^^^^^^^^^^^^
  File "C:\Users\User\Desktop\Django\venv\Lib\site-packages\django\template\base.py", line 969, in render_annotated
    return self.render(context)
           ^^^^^^^^^^^^^^^^^^^^
  File "C:\Users\User\Desktop\Django\venv\Lib\site-packages\django\template\base.py", line 1067, in render
    output = self.filter_expression.resolve(context)
             ^^^^^^^^^^^^^^^^^^^^^^^^^^^^^^^^^^^^^^^
  File "C:\Users\User\Desktop\Django\venv\Lib\site-packages\django\template\base.py", line 745, in resolve
    new_obj = func(obj, *arg_vals)
              ^^^^^^^^^^^^^^^^^^^^
  File "C:\Users\User\Desktop\Django\venv\Lib\site-packages\crispy_forms\templatetags\crispy_forms_filters.py", line 58, in as_crispy_form
    template = uni_form_template(template_pack)
               ^^^^^^^^^^^^^^^^^^^^^^^^^^^^^^^^
  File "C:\Users\User\Desktop\Django\venv\Lib\site-packages\crispy_forms\templatetags\crispy_forms_filters.py", line 21, in uni_form_template
    return get_template("%s/uni_form.html" % template_pack)
           ^^^^^^^^^^^^^^^^^^^^^^^^^^^^^^^^^^^^^^^^^^^^^^^^
  File "C:\Users\User\Desktop\Django\venv\Lib\site-packages\django\template\loader.py", line 19, in get_template
    raise TemplateDoesNotExist(template_name, chain=chain)
django.template.exceptions.TemplateDoesNotExist: bootstrap4/uni_form.html

The above exception was the direct cause of the following exception:

Traceback (most recent call last):
  File "C:\Users\User\Desktop\Django\venv\Lib\site-packages\django\core\handlers\exception.py", line 55, in inner
    response = get_response(request)
               ^^^^^^^^^^^^^^^^^^^^^
  File "C:\Users\User\Desktop\Django\venv\Lib\site-packages\django\core\handlers\base.py", line 197, in _get_response
    response = wrapped_callback(request, *callback_args, **callback_kwargs)
               ^^^^^^^^^^^^^^^^^^^^^^^^^^^^^^^^^^^^^^^^^^^^^^^^^^^^^^^^^^^^
  File "C:\Users\User\Desktop\Django\venv\Lib\site-packages\django\views\generic\base.py", line 104, in view
    return self.dispatch(request, *args, **kwargs)
           ^^^^^^^^^^^^^^^^^^^^^^^^^^^^^^^^^^^^^^^
  File "C:\Users\User\Desktop\Django\venv\Lib\site-packages\django\contrib\auth\mixins.py", line 73, in dispatch
    return super().dispatch(request, *args, **kwargs)
           ^^^^^^^^^^^^^^^^^^^^^^^^^^^^^^^^^^^^^^^^^^
  File "C:\Users\User\Desktop\Django\venv\Lib\site-packages\django\views\generic\base.py", line 143, in dispatch
    return handler(request, *args, **kwargs)
           ^^^^^^^^^^^^^^^^^^^^^^^^^^^^^^^^^
  File "C:\Users\User\Desktop\Django\facility\views.py", line 81, in get
    return render(request=self.request, template_name=self.template_name, context=context)
           ^^^^^^^^^^^^^^^^^^^^^^^^^^^^^^^^^^^^^^^^^^^^^^^^^^^^^^^^^^^^^^^^^^^^^^^^^^^^^^^
  File "C:\Users\User\Desktop\Django\venv\Lib\site-packages\django\shortcuts.py", line 25, in render
    content = loader.render_to_string(template_name, context, request, using=using)
              ^^^^^^^^^^^^^^^^^^^^^^^^^^^^^^^^^^^^^^^^^^^^^^^^^^^^^^^^^^^^^^^^^^^^^
  File "C:\Users\User\Desktop\Django\venv\Lib\site-packages\django\template\loader.py", line 62, in render_to_string
    return template.render(context, request)
           ^^^^^^^^^^^^^^^^^^^^^^^^^^^^^^^^^
  File "C:\Users\User\Desktop\Django\venv\Lib\site-packages\django\template\backends\django.py", line 109, in render
    reraise(exc, self.backend)
  File "C:\Users\User\Desktop\Django\venv\Lib\site-packages\django\template\backends\django.py", line 130, in reraise
    raise new from exc
django.template.exceptions.TemplateDoesNotExist: bootstrap4/uni_form.html
