2025-02-23 14:30:29,787 [INFO]- Watching for file changes with StatReloader
2025-02-23 14:30:54,695 [INFO]- "GET / HTTP/1.1" 200 3830
2025-02-23 14:30:54,769 [INFO]- "GET /facility_mgnstatic/assets/css/bootstrap.css HTTP/1.1" 200 126499
2025-02-23 14:30:54,777 [INFO]- "GET /facility_mgnstatic/assets/css/font-awesome.css HTTP/1.1" 200 21743
2025-02-23 14:30:54,800 [INFO]- "GET /facility_mgnstatic/assets/css/custom-styles.css HTTP/1.1" 200 7745
2025-02-23 14:30:54,824 [INFO]- "GET /facility_mgnstatic/assets/js/morris/raphael-2.1.0.min.js HTTP/1.1" 200 90647
2025-02-23 14:30:54,834 [INFO]- "GET /facility_mgnstatic/assets/js/morris/morris-0.4.3.min.css HTTP/1.1" 200 443
2025-02-23 14:30:54,846 [INFO]- "GET /facility_mgnstatic/assets/js/jquery.metisMenu.js HTTP/1.1" 200 1386
2025-02-23 14:30:54,883 [INFO]- "GET /facility_mgnstatic/assets/js/custom-scripts.js HTTP/1.1" 200 5909
2025-02-23 14:30:54,917 [INFO]- "GET /facility_mgnstatic/assets/js/morris/morris.js HTTP/1.1" 200 67203
2025-02-23 14:30:54,981 [INFO]- "GET /facility_mgnstatic/assets/js/jquery-1.10.2.js HTTP/1.1" 200 293285
2025-02-23 14:30:55,015 [INFO]- "GET /facility_mgnstatic/assets/js/bootstrap.min.js HTTP/1.1" 200 29097
2025-02-23 14:30:55,644 [INFO]- "GET /facility_mgnstatic/core/repairman.webp HTTP/1.1" 200 178036
2025-02-23 14:30:55,751 [WARNING]- Not Found: /favicon.ico
2025-02-23 14:30:55,751 [WARNING]- Not Found: /favicon.ico
2025-02-23 14:30:55,757 [WARNING]- "GET /favicon.ico HTTP/1.1" 404 4701
2025-02-23 14:30:59,200 [INFO]- "GET /register/ HTTP/1.1" 200 4926
2025-02-23 14:32:16,428 [INFO]- "POST /register/ HTTP/1.1" 302 0
2025-02-23 14:32:16,440 [INFO]- "GET /login/ HTTP/1.1" 200 3949
2025-02-23 14:32:37,417 [INFO]- "POST /login/ HTTP/1.1" 302 0
2025-02-23 14:32:37,439 [INFO]- "GET /dashboard/ HTTP/1.1" 302 0
2025-02-23 14:32:37,531 [INFO]- "GET /dashboard/student/ HTTP/1.1" 200 7834
2025-02-23 14:32:37,644 [INFO]- "GET /facility_mgnstatic/assets/font-awesome/fonts/fontawesome-webfontba72.woff?v=4.0.3 HTTP/1.1" 200 44432
2025-02-23 14:32:41,141 [INFO]- "GET /facility/report/add/ HTTP/1.1" 200 5492
2025-02-23 14:33:11,040 [INFO]- "POST /facility/report/add/ HTTP/1.1" 302 0
2025-02-23 14:33:11,138 [INFO]- "GET /facility/report/list/ HTTP/1.1" 200 8105
2025-02-23 14:33:18,034 [INFO]- "GET /facility/report/list/?user_type=technician HTTP/1.1" 200 5700
2025-02-23 14:33:19,999 [INFO]- "GET /dashboard/ HTTP/1.1" 302 0
2025-02-23 14:33:20,022 [INFO]- "GET /dashboard/student/ HTTP/1.1" 200 8524
2025-02-23 14:33:25,441 [ERROR]- Internal Server Error: /facility/report/details/13001232CS/
Traceback (most recent call last):
  File "C:\Users\User\Desktop\Django\venv\Lib\site-packages\django\template\backends\django.py", line 107, in render
    return self.template.render(context)
           ^^^^^^^^^^^^^^^^^^^^^^^^^^^^^
  File "C:\Users\User\Desktop\Django\venv\Lib\site-packages\django\template\base.py", line 171, in render
    return self._render(context)
           ^^^^^^^^^^^^^^^^^^^^^
  File "C:\Users\User\Desktop\Django\venv\Lib\site-packages\django\test\utils.py", line 114, in instrumented_test_render
    return self.nodelist.render(context)
           ^^^^^^^^^^^^^^^^^^^^^^^^^^^^^
  File "C:\Users\User\Desktop\Django\venv\Lib\site-packages\django\template\base.py", line 1008, in render
    return SafeString("".join([node.render_annotated(context) for node in self]))
                               ^^^^^^^^^^^^^^^^^^^^^^^^^^^^^^
  File "C:\Users\User\Desktop\Django\venv\Lib\site-packages\django\template\base.py", line 969, in render_annotated
    return self.render(context)
           ^^^^^^^^^^^^^^^^^^^^
  File "C:\Users\User\Desktop\Django\venv\Lib\site-packages\django\template\loader_tags.py", line 159, in render
    return compiled_parent._render(context)
           ^^^^^^^^^^^^^^^^^^^^^^^^^^^^^^^^
  File "C:\Users\User\Desktop\Django\venv\Lib\site-packages\django\test\utils.py", line 114, in instrumented_test_render
    return self.nodelist.render(context)
           ^^^^^^^^^^^^^^^^^^^^^^^^^^^^^
  File "C:\Users\User\Desktop\Django\venv\Lib\site-packages\django\template\base.py", line 1008, in render
    return SafeString("".join([node.render_annotated(context) for node in self]))
                               ^^^^^^^^^^^^^^^^^^^^^^^^^^^^^^
  File "C:\Users\User\Desktop\Django\venv\Lib\site-packages\django\template\base.py", line 969, in render_annotated
    return self.render(context)
           ^^^^^^^^^^^^^^^^^^^^
  File "C:\Users\User\Desktop\Django\venv\Lib\site-packages\django\template\loader_tags.py", line 65, in render
    result = block.nodelist.render(context)
             ^^^^^^^^^^^^^^^^^^^^^^^^^^^^^^
  File "C:\Users\User\Desktop\Django\venv\Lib\site-packages\django\template\base.py", line 1008, in render
    return SafeString("".join([node.render_annotated(context) for node in self]))
                               ^^^^^^^^^^^^^^^^^^^^^^^^^^^^^^
  File "C:\Users\User\Desktop\Django\venv\Lib\site-packages\django\template\base.py", line 969, in render_annotated
    return self.render(context)
           ^^^^^^^^^^^^^^^^^^^^
  File "C:\Users\User\Desktop\Django\venv\Lib\site-packages\django\template\base.py", line 1067, in render
    output = self.filter_expression.resolve(context)
             ^^^^^^^^^^^^^^^^^^^^^^^^^^^^^^^^^^^^^^^
  File "C:\Users\User\Desktop\Django\venv\Lib\site-packages\django\template\base.py", line 745, in resolve
    new_obj = func(obj, *arg_vals)
              ^^^^^^^^^^^^^^^^^^^^
  File "C:\Users\User\Desktop\Django\venv\Lib\site-packages\crispy_forms\templatetags\crispy_forms_filters.py", line 58, in as_crispy_form
    template = uni_form_template(template_pack)
               ^^^^^^^^^^^^^^^^^^^^^^^^^^^^^^^^
  File "C:\Users\User\Desktop\Django\venv\Lib\site-packages\crispy_forms\templatetags\crispy_forms_filters.py", line 21, in uni_form_template
    return get_template("%s/uni_form.html" % template_pack)
           ^^^^^^^^^^^^^^^^^^^^^^^^^^^^^^^^^^^^^^^^^^^^^^^^
  File "C:\Users\User\Desktop\Django\venv\Lib\site-packages\django\template\loader.py", line 19, in get_template
    raise TemplateDoesNotExist(template_name, chain=chain)
django.template.exceptions.TemplateDoesNotExist: bootstrap4/uni_form.html

The above exception was the direct cause of the following exception:

Traceback (most recent call last):
  File "C:\Users\User\Desktop\Django\venv\Lib\site-packages\django\core\handlers\exception.py", line 55, in inner
    response = get_response(request)
               ^^^^^^^^^^^^^^^^^^^^^
  File "C:\Users\User\Desktop\Django\venv\Lib\site-packages\django\core\handlers\base.py", line 197, in _get_response
    response = wrapped_callback(request, *callback_args, **callback_kwargs)
               ^^^^^^^^^^^^^^^^^^^^^^^^^^^^^^^^^^^^^^^^^^^^^^^^^^^^^^^^^^^^
  File "C:\Users\User\Desktop\Django\venv\Lib\site-packages\django\views\generic\base.py", line 104, in view
    return self.dispatch(request, *args, **kwargs)
           ^^^^^^^^^^^^^^^^^^^^^^^^^^^^^^^^^^^^^^^
  File "C:\Users\User\Desktop\Django\venv\Lib\site-packages\django\contrib\auth\mixins.py", line 73, in dispatch
    return super().dispatch(request, *args, **kwargs)
           ^^^^^^^^^^^^^^^^^^^^^^^^^^^^^^^^^^^^^^^^^^
  File "C:\Users\User\Desktop\Django\venv\Lib\site-packages\django\views\generic\base.py", line 143, in dispatch
    return handler(request, *args, **kwargs)
           ^^^^^^^^^^^^^^^^^^^^^^^^^^^^^^^^^
  File "C:\Users\User\Desktop\Django\facility\views.py", line 81, in get
    return render(request=self.request, template_name=self.template_name, context=context)
           ^^^^^^^^^^^^^^^^^^^^^^^^^^^^^^^^^^^^^^^^^^^^^^^^^^^^^^^^^^^^^^^^^^^^^^^^^^^^^^^
  File "C:\Users\User\Desktop\Django\venv\Lib\site-packages\django\shortcuts.py", line 25, in render
    content = loader.render_to_string(template_name, context, request, using=using)
              ^^^^^^^^^^^^^^^^^^^^^^^^^^^^^^^^^^^^^^^^^^^^^^^^^^^^^^^^^^^^^^^^^^^^^
  File "C:\Users\User\Desktop\Django\venv\Lib\site-packages\django\template\loader.py", line 62, in render_to_string
    return template.render(context, request)
           ^^^^^^^^^^^^^^^^^^^^^^^^^^^^^^^^^
  File "C:\Users\User\Desktop\Django\venv\Lib\site-packages\django\template\backends\django.py", line 109, in render
    reraise(exc, self.backend)
  File "C:\Users\User\Desktop\Django\venv\Lib\site-packages\django\template\backends\django.py", line 130, in reraise
    raise new from exc
django.template.exceptions.TemplateDoesNotExist: bootstrap4/uni_form.html
2025-02-23 14:33:25,441 [ERROR]- Internal Server Error: /facility/report/details/13001232CS/
Traceback (most recent call last):
  File "C:\Users\User\Desktop\Django\venv\Lib\site-packages\django\template\backends\django.py", line 107, in render
    return self.template.render(context)
           ^^^^^^^^^^^^^^^^^^^^^^^^^^^^^
  File "C:\Users\User\Desktop\Django\venv\Lib\site-packages\django\template\base.py", line 171, in render
    return self._render(context)
           ^^^^^^^^^^^^^^^^^^^^^
  File "C:\Users\User\Desktop\Django\venv\Lib\site-packages\django\test\utils.py", line 114, in instrumented_test_render
    return self.nodelist.render(context)
           ^^^^^^^^^^^^^^^^^^^^^^^^^^^^^
  File "C:\Users\User\Desktop\Django\venv\Lib\site-packages\django\template\base.py", line 1008, in render
    return SafeString("".join([node.render_annotated(context) for node in self]))
                               ^^^^^^^^^^^^^^^^^^^^^^^^^^^^^^
  File "C:\Users\User\Desktop\Django\venv\Lib\site-packages\django\template\base.py", line 969, in render_annotated
    return self.render(context)
           ^^^^^^^^^^^^^^^^^^^^
  File "C:\Users\User\Desktop\Django\venv\Lib\site-packages\django\template\loader_tags.py", line 159, in render
    return compiled_parent._render(context)
           ^^^^^^^^^^^^^^^^^^^^^^^^^^^^^^^^
  File "C:\Users\User\Desktop\Django\venv\Lib\site-packages\django\test\utils.py", line 114, in instrumented_test_render
    return self.nodelist.render(context)
           ^^^^^^^^^^^^^^^^^^^^^^^^^^^^^
  File "C:\Users\User\Desktop\Django\venv\Lib\site-packages\django\template\base.py", line 1008, in render
    return SafeString("".join([node.render_annotated(context) for node in self]))
                               ^^^^^^^^^^^^^^^^^^^^^^^^^^^^^^
  File "C:\Users\User\Desktop\Django\venv\Lib\site-packages\django\template\base.py", line 969, in render_annotated
    return self.render(context)
           ^^^^^^^^^^^^^^^^^^^^
  File "C:\Users\User\Desktop\Django\venv\Lib\site-packages\django\template\loader_tags.py", line 65, in render
    result = block.nodelist.render(context)
             ^^^^^^^^^^^^^^^^^^^^^^^^^^^^^^
  File "C:\Users\User\Desktop\Django\venv\Lib\site-packages\django\template\base.py", line 1008, in render
    return SafeString("".join([node.render_annotated(context) for node in self]))
                               ^^^^^^^^^^^^^^^^^^^^^^^^^^^^^^
  File "C:\Users\User\Desktop\Django\venv\Lib\site-packages\django\template\base.py", line 969, in render_annotated
    return self.render(context)
           ^^^^^^^^^^^^^^^^^^^^
  File "C:\Users\User\Desktop\Django\venv\Lib\site-packages\django\template\base.py", line 1067, in render
    output = self.filter_expression.resolve(context)
             ^^^^^^^^^^^^^^^^^^^^^^^^^^^^^^^^^^^^^^^
  File "C:\Users\User\Desktop\Django\venv\Lib\site-packages\django\template\base.py", line 745, in resolve
    new_obj = func(obj, *arg_vals)
              ^^^^^^^^^^^^^^^^^^^^
  File "C:\Users\User\Desktop\Django\venv\Lib\site-packages\crispy_forms\templatetags\crispy_forms_filters.py", line 58, in as_crispy_form
    template = uni_form_template(template_pack)
               ^^^^^^^^^^^^^^^^^^^^^^^^^^^^^^^^
  File "C:\Users\User\Desktop\Django\venv\Lib\site-packages\crispy_forms\templatetags\crispy_forms_filters.py", line 21, in uni_form_template
    return get_template("%s/uni_form.html" % template_pack)
           ^^^^^^^^^^^^^^^^^^^^^^^^^^^^^^^^^^^^^^^^^^^^^^^^
  File "C:\Users\User\Desktop\Django\venv\Lib\site-packages\django\template\loader.py", line 19, in get_template
    raise TemplateDoesNotExist(template_name, chain=chain)
django.template.exceptions.TemplateDoesNotExist: bootstrap4/uni_form.html

The above exception was the direct cause of the following exception:

Traceback (most recent call last):
  File "C:\Users\User\Desktop\Django\venv\Lib\site-packages\django\core\handlers\exception.py", line 55, in inner
    response = get_response(request)
               ^^^^^^^^^^^^^^^^^^^^^
  File "C:\Users\User\Desktop\Django\venv\Lib\site-packages\django\core\handlers\base.py", line 197, in _get_response
    response = wrapped_callback(request, *callback_args, **callback_kwargs)
               ^^^^^^^^^^^^^^^^^^^^^^^^^^^^^^^^^^^^^^^^^^^^^^^^^^^^^^^^^^^^
  File "C:\Users\User\Desktop\Django\venv\Lib\site-packages\django\views\generic\base.py", line 104, in view
    return self.dispatch(request, *args, **kwargs)
           ^^^^^^^^^^^^^^^^^^^^^^^^^^^^^^^^^^^^^^^
  File "C:\Users\User\Desktop\Django\venv\Lib\site-packages\django\contrib\auth\mixins.py", line 73, in dispatch
    return super().dispatch(request, *args, **kwargs)
           ^^^^^^^^^^^^^^^^^^^^^^^^^^^^^^^^^^^^^^^^^^
  File "C:\Users\User\Desktop\Django\venv\Lib\site-packages\django\views\generic\base.py", line 143, in dispatch
    return handler(request, *args, **kwargs)
           ^^^^^^^^^^^^^^^^^^^^^^^^^^^^^^^^^
  File "C:\Users\User\Desktop\Django\facility\views.py", line 81, in get
    return render(request=self.request, template_name=self.template_name, context=context)
           ^^^^^^^^^^^^^^^^^^^^^^^^^^^^^^^^^^^^^^^^^^^^^^^^^^^^^^^^^^^^^^^^^^^^^^^^^^^^^^^
  File "C:\Users\User\Desktop\Django\venv\Lib\site-packages\django\shortcuts.py", line 25, in render
    content = loader.render_to_string(template_name, context, request, using=using)
              ^^^^^^^^^^^^^^^^^^^^^^^^^^^^^^^^^^^^^^^^^^^^^^^^^^^^^^^^^^^^^^^^^^^^^
  File "C:\Users\User\Desktop\Django\venv\Lib\site-packages\django\template\loader.py", line 62, in render_to_string
    return template.render(context, request)
           ^^^^^^^^^^^^^^^^^^^^^^^^^^^^^^^^^
  File "C:\Users\User\Desktop\Django\venv\Lib\site-packages\django\template\backends\django.py", line 109, in render
    reraise(exc, self.backend)
  File "C:\Users\User\Desktop\Django\venv\Lib\site-packages\django\template\backends\django.py", line 130, in reraise
    raise new from exc
django.template.exceptions.TemplateDoesNotExist: bootstrap4/uni_form.html
2025-02-23 14:33:25,462 [ERROR]- "GET /facility/report/details/13001232CS/ HTTP/1.1" 500 190854
